Workbook

Sheet README
B2: Х10 DAILY
B3: Финансовая модель · 12 месяцев · v1.0
B4: Бизнес-Практика → ежедневное медиа · период: июнь 2026 — май 2027
B6: 80 000 DAU · 2 000 платных · ~36 М ₽ ARR · кэш-нейтрал в Q3 2026
A9: СОДЕРЖАНИЕ МОДЕЛИ
B10: Допущения | C10: Все драйверы модели в одном месте. Меняй синие ячейки → пересчитается всё.
B11: Воронка | C11: Привлечение по каналам, конверсия в DAU, retention. M1–M12 помесячно.
B12: Доходы | C12: Premium-подписки, события, печать. MRR, ARR, помесячная выручка.
B13: Расходы | C13: ФОТ команды, инфраструктура, AI, маркетинг, события, юр/бух. Помесячно.
B14: P&L | C14: Отчёт о прибылях и убытках: выручка, COGS, OpEx, EBITDA, маржа.
B15: Cashflow | C15: Движение денежных средств: поступления, выплаты, кумулятивный остаток.
B16: Юнит-экономика | C16: CAC по каналам, LTV, payback, contribution margin, LTV/CAC.
B17: Сценарии | C17: Bear / Base / Bull — что происходит при разных уровнях конверсии и retention.
B18: Dashboard | C18: Сводка ключевых KPI и графики: DAU, paid, MRR, cash.
A21: ЦВЕТОВОЙ КОД
B22: Синий шрифт | C22: Вход. Меняй эти ячейки для what-if анализа.
B23: Чёрный шрифт | C23: Формула. Не трогай — пересчитается автоматически.
B24: Зелёный шрифт | C24: Ссылка на другой лист книги.
B25: Жёлтая заливка | C25: Ключевой рычаг модели. Меняет результат больше всего.
B26: Красная плашка | C26: Заголовок раздела (бренд Х10).
A29: ИСТОЧНИКИ ДАННЫХ
B30: Стратегия v1.0 | C30: X10Strategyv1_0.pdf — все таргеты по DAU, paid, бюджету
B31: Бенчмарк нишевых медиа | C31: Morning Brew, Stratechery, The Information, Sifted, Lenny's — конверсии и retention
B32: Х10 community | C32: x10movement.ru — 30 885 кламперов на старте
B33: Рыбаков media | C33: ~6 млн подписчиков (YouTube 2.6M, IG 1M, TT 2.1M, TG 156K)
B34: Затраты — рынок РФ | C34: ФОТ — медианы hh.ru для редакторских/инженерных позиций 2025–2026
A37: КАК РАБОТАТЬ С МОДЕЛЬЮ
B38: 1. Стартовая точка | C38: Лист «Допущения». Все базовые гипотезы — там.
B39: 2. Главные рычаги | C39: Жёлтые ячейки: конверсия free→paid, retention, CAC. Меняй их в первую очередь.
B40: 3. What-if быстро | C40: Лист «Сценарии» — три заранее посчитанных варианта (Bear/Base/Bull).
B41: 4. Триггеры пересборки | C41: Если paid <1% за 6 мес — Bear-сценарий. Если retention <25% — пересборка дайджеста.
B42: 5. Контрольные точки | C42: Лист «Dashboard» — там KPI vs план по кварталам.
B46: Конфиденциально · Х10 / Бизнес-Практика · 25 мая 2026

Sheet Допущения
B2: ДОПУЩЕНИЯ МОДЕЛИ
B4: Параметр | C4: Значение | D4: Ед. | E4: Источник / комментарий
A6: 1. БАЗА АУДИТОРИИ (стартовые пулы)
B7: База Х10 — действующие кламперы | C7: 30885 | D7: чел | E7: x10movement.ru, май 2026
B8: Рыбаков · YouTube | C8: 2600000 | D8: чел | E8: Forbes.ru, 2025
B9: Рыбаков · Telegram | C9: 156000 | D9: чел | E9: канал @rybakov_igor
B10: Рыбаков · Instagram | C10: 1000000 | D10: чел | E10: @rybakov_igor
B11: Рыбаков · TikTok | C11: 2100000 | D11: чел | E11: TikTok аналитика, 2025
B12: Поправка на пересечение каналов | C12: 0.3 | D12: % | E12: 30% уникальной активной аудитории из суммы
B13: Сумма подписчиков Рыбакова (брутто) | C13: =SUM(Допущения!$C$8,Допущения!$C$9,Допущения!$C$10,Допущения!$C$11) -> 5856000 | D13: чел
B14: Активная уникальная база (с поправкой на overlap) | C14: =Допущения!$C$13*Допущения!$C$12 -> 1756800 | D14: чел
A16: 2. ВОРОНКА ПРИВЛЕЧЕНИЯ — конверсии по каналам
B17: Канал 1: Х10 community — organic
B18: Совокупная конверсия базы Х10 в installs за 12 мес | C18: 0.85 | D18: % | E18: из 30 885 → 26K installs (хайп-канал)
B19: Доля установок в Q1 от 12-мес итога | C19: 0.55 | D19: % | E19: ранние юзеры заходят в Q1
B20: Доля установок в Q2 | C20: 0.25 | D20: %
B21: Доля установок в Q3 | C21: 0.12 | D21: %
B22: Доля установок в Q4 | C22: 0.08 | D22: % | E22: сумма = 100%
B24: Канал 2: Рыбаков media — organic (TG/YT/IG/TT)
B25: Месячная конверсия активной базы в installs | C25: 0.005 | D25: % | E25: 0.5%/мес — с прямым CTA в каждом ролике
B26: Усиление со 2-го квартала (CTA в роликах) | C26: 1.6 | D26: x | E26: множитель к месячной конверсии после M3
B28: Канал 3: Реферальная программа (Morning Brew model)
B29: Месяц запуска реферальной программы | C29: 4 | D29: М | E29: M4 — после стабилизации MVP
B30: K-фактор: средн. рефералов на 1 активного юзера / мес | C30: 0.04 | D30: x | E30: Morning Brew benchmark ~0.05–0.08
B31: Конверсия приглашённых в install | C31: 0.4 | D31: % | E31: высокая — приходят по доверию
B33: Канал 4: Платный трафик (TG Ads + посевы)
B34: CAC платного канала (1 install) | C34: 150 | D34: ₽ | E34: цель стратегии · TG Ads + блогеры
B35: Маркетинговый бюджет / мес (Q1) | C35: 150000 | D35: ₽/мес | E35: разогрев, тесты
B36: Маркетинговый бюджет / мес (Q2) | C36: 350000 | D36: ₽/мес | E36: push на 25K DAU
B37: Маркетинговый бюджет / мес (Q3) | C37: 250000 | D37: ₽/мес | E37: органика берёт верх
B38: Маркетинговый бюджет / мес (Q4) | C38: 200000 | D38: ₽/мес | E38: реинвест из выручки
B40: Канал 5: PR / earned media (выступления, СМИ, упоминания)
B41: Installs/мес — старт | C41: 200 | D41: чел/мес | E41: консервативно
B42: Installs/мес — Q4 | C42: 1500 | D42: чел/мес | E42: репутация набирается
A45: 3. УДЕРЖАНИЕ И ВОВЛЕЧЕНИЕ
B46: Активация: install → 7-дневный active | C46: 0.65 | D46: % | E46: стандарт для daily media
B47: W4 retention (Q1 cohort) | C47: 0.32 | D47: % | E47: цель стратегии ≥30%
B48: W4 retention (Q2 cohort) | C48: 0.38 | D48: % | E48: цель ≥38% после улучшений
B49: W4 retention (Q3 cohort) | C49: 0.42 | D49: % | E49: AI-персонализация запущена
B50: W4 retention (Q4 cohort) | C50: 0.45 | D50: % | E50: зрелый продукт
...

Sheet Воронка
A2: ВОРОНКА ПРИВЛЕЧЕНИЯ — каналы → DAU
B4: Q1 | C4: Q1 | D4: Q1 | E4: Q2 | F4: Q2 | G4: Q2 | H4: Q3 | I4: Q3 | J4: Q3 | K4: Q4 | L4: Q4 | M4: Q4
B5: М1 июн '26 | C5: М2 июл '26 | D5: М3 авг '26 | E5: М4 сен '26 | F5: М5 окт '26 | G5: М6 ноя '26 | H5: М7 дек '26 | I5: М8 янв '27 | J5: М9 фев '27 | K5: М10 мар '27 | L5: М11 апр '27 | M5: М12 май '27 | N5: ИТОГО год
A6: A. УСТАНОВКИ ПО КАНАЛАМ (помесячно)
A7: Канал 1 · Х10 Community organic
A8: установки/мес (Х10) | B8: =Допущения!$C$7*Допущения!$C$18*Допущения!$C$19/3 -> 4812.9125 | C8: =Допущения!$C$7*Допущения!$C$18*Допущения!$C$19/3 -> 4812.9125 | D8: =Допущения!$C$7*Допущения!$C$18*Допущения!$C$19/3 -> 4812.9125 | E8: =Допущения!$C$7*Допущения!$C$18*Допущения!$C$20/3 -> 2187.6875 | F8: =Допущения!$C$7*Допущения!$C$18*Допущения!$C$20/3 -> 2187.6875 | G8: =Допущения!$C$7*Допущения!$C$18*Допущения!$C$20/3 -> 2187.6875 | H8: =Допущения!$C$7*Допущения!$C$18*Допущения!$C$21/3 -> 1050.09 | I8: =Допущения!$C$7*Допущения!$C$18*Допущения!$C$21/3 -> 1050.09 | J8: =Допущения!$C$7*Допущения!$C$18*Допущения!$C$21/3 -> 1050.09 | K8: =Допущения!$C$7*Допущения!$C$18*Допущения!$C$22/3 -> 700.06 | L8: =Допущения!$C$7*Допущения!$C$18*Допущения!$C$22/3 -> 700.06 | M8: =Допущения!$C$7*Допущения!$C$18*Допущения!$C$22/3 -> 700.06 | N8: =SUM(B8:M8) -> 26252.25
A10: Канал 2 · Рыбаков organic (TG/YT/IG/TT)
A11: установки/мес (Рыбаков) | B11: =Допущения!$C$14*Допущения!$C$25*1 -> 8784 | C11: =Допущения!$C$14*Допущения!$C$25*1 -> 8784 | D11: =Допущения!$C$14*Допущения!$C$25*1 -> 8784 | E11: =Допущения!$C$14*Допущения!$C$25*Допущения!$C$26 -> 14054.4 | F11: =Допущения!$C$14*Допущения!$C$25*Допущения!$C$26 -> 14054.4 | G11: =Допущения!$C$14*Допущения!$C$25*Допущения!$C$26 -> 14054.4 | H11: =Допущения!$C$14*Допущения!$C$25*Допущения!$C$26 -> 14054.4 | I11: =Допущения!$C$14*Допущения!$C$25*Допущения!$C$26 -> 14054.4 | J11: =Допущения!$C$14*Допущения!$C$25*Допущения!$C$26 -> 14054.4 | K11: =Допущения!$C$14*Допущения!$C$25*Допущения!$C$26 -> 14054.4 | L11: =Допущения!$C$14*Допущения!$C$25*Допущения!$C$26 -> 14054.4 | M11: =Допущения!$C$14*Допущения!$C$25*Допущения!$C$26 -> 14054.4 | N11: =SUM(B11:M11) -> 152841.6
A13: Канал 3 · Платный трафик (TG Ads + посевы)
A14: бюджет/мес | B14: =Допущения!$C$35 -> 150000 | C14: =Допущения!$C$35 -> 150000 | D14: =Допущения!$C$35 -> 150000 | E14: =Допущения!$C$36 -> 350000 | F14: =Допущения!$C$36 -> 350000 | G14: =Допущения!$C$36 -> 350000 | H14: =Допущения!$C$37 -> 250000 | I14: =Допущения!$C$37 -> 250000 | J14: =Допущения!$C$37 -> 250000 | K14: =Допущения!$C$38 -> 200000 | L14: =Допущения!$C$38 -> 200000 | M14: =Допущения!$C$38 -> 200000 | N14: =SUM(B14:M14) -> 2850000
A15: установки/мес (платно) | B15: =B14/Допущения!$C$34 -> 1000 | C15: =C14/Допущения!$C$34 -> 1000 | D15: =D14/Допущения!$C$34 -> 1000 | E15: =E14/Допущения!$C$34 -> 2333.3333 | F15: =F14/Допущения!$C$34 -> 2333.3333 | G15: =G14/Допущения!$C$34 -> 2333.3333 | H15: =H14/Допущения!$C$34 -> 1666.6667 | I15: =I14/Допущения!$C$34 -> 1666.6667 | ... M15: =M14/Допущения!$C$34 -> 1333.3333 | N15: =SUM(B15:M15) -> 19000
A17: Канал 4 · PR / earned media
A18: установки/мес (PR) | B18: =Допущения!$C$41+(Допущения!$C$42-Допущения!$C$41)*(1-1)/11 -> 200 | C18: =Допущения!$C$41+(Допущения!$C$42-Допущения!$C$41)*(2-1)/11 -> 318.18182 | D18: =Допущения!$C$41+(Допущения!$C$42-Допущения!$C$41)*(3-1)/11 -> 436.36364 | E18: =Допущения!$C$41+(Допущения!$C$42-Допущения!$C$41)*(4-1)/11 -> 554.54545 | F18: =Допущения!$C$41+(Допущения!$C$42-Допущения!$C$41)*(5-1)/11 -> 672.72727 | G18: =Допущения!$C$41+(Допущения!$C$42-Допущения!$C$41)*(6-1)/11 -> 790.90909 | H18: =Допущения!$C$41+(Допущения!$C$42-Допущения!$C$41)*(7-1)/11 -> 909.09091 | I18: =Допущения!$C$41+(Допущения!$C$42-Допущения!$C$41)*(8-1)/11 -> 1027.2727 | J18: =Допущения!$C$41+(Допущения!$C$42-Допущения!$C$41)*(9-1)/11 -> 1145.4545 | K18: =Допущения!$C$41+(Допущения!$C$42-Допущения!$C$41)*(10-1)/11 -> 1263.6364 | L18: =Допущения!$C$41+(Допущения!$C$42-Допущения!$C$41)*(11-1)/11 -> 1381.8182 | M18: =Допущения!$C$41+(Допущения!$C$42-Допущения!$C$41)*(12-1)/11 -> 1500 | N18: =SUM(B18:M18) -> 10200
A20: Канал 5 · Реферальная программа
A21: установки/мес (рефералы) | B21: =0 -> 0 | C21: =0 -> 0 | D21: =0 -> 0 | E21: =IF(4<Допущения!$C$29,0,D29*Допущения!$C$30*Допущения!$C$31) -> 207.06488 | F21: =IF(5<Допущения!$C$29,0,E29*Допущения!$C$30*Допущения!$C$31) -> 303.92755 | G21: =IF(6<Допущения!$C$29,0,F29*Допущения!$C$30*Допущения!$C$31) -> 392.41141 | H21: =IF(7<Допущения!$C$29,0,G29*Допущения!$C$30*Допущения!$C$31) -> 473.30342 | I21: =IF(8<Допущения!$C$29,0,H29*Допущения!$C$30*Допущения!$C$31) -> 547.96494 | J21: =IF(9<Допущения!$C$29,0,I29*Допущения!$C$30*Допущения!$C$31) -> 616.45621 | K21: =IF(10<Допущения!$C$29,0,J29*Допущения!$C$30*Допущения!$C$31) -> 679.35281 | L21: =IF(11<Допущения!$C$29,0,K29*Допущения!$C$30*Допущения!$C$31) -> 741.23916 | M21: =IF(12<Допущения!$C$29,0,L29*Допущения!$C$30*Допущения!$C$31) -> 798.23337 | N21: =SUM(B21:M21) -> 4759.9537
A23: ВСЕГО УСТАНОВОК / МЕС | B23: =SUM(B8,B11,B15,B18,B21) -> 14796.913 | C23: =SUM(C8,C11,C15,C18,C21) -> 14915.094 | D23: =SUM(D8,D11,D15,D18,D21) -> 15033.276 | E23: =SUM(E8,E11,E15,E18,E21) -> 19337.031 | F23: =SUM(F8,F11,F15,F18,F21) -> 19552.076 | G23: =SUM(G8,G11,G15,G18,G21) -> 19758.741 | H23: =SUM(H8,H11,H15,H18,H21) -> 18153.551 | I23: =SUM(I8,I11,I15,I18,I21) -> 18346.394 | ... M23: =SUM(M8,M11,M15,M18,M21) -> 18386.027 | N23: =SUM(B23:M23) -> 213053.8
A24: накопленные установки | B24: =SUM($B$23:B23) -> 14796.913 | C24: =SUM($B$23:C23) -> 29712.007 | D24: =SUM($B$23:D23) -> 44745.283 | E24: =SUM($B$23:E23) -> 64082.314 | F24: =SUM($B$23:F23) -> 83634.39 | G24: =SUM($B$23:G23) -> 103393.13 | H24: =SUM($B$23:H23) -> 121546.68 | I24: =SUM($B$23:I23) -> 139893.08 | ... M24: =SUM($B$23:M23) -> 213053.8
A26: B. MAU / DAU — модель удержания
A27: W4 retention (для текущего квартала) | B27: =Допущения!$C$47 -> 0.32 | C27: =Допущения!$C$47 -> 0.32 | D27: =Допущения!$C$47 -> 0.32 | E27: =Допущения!$C$48 -> 0.38 | F27: =Допущения!$C$48 -> 0.38 | G27: =Допущения!$C$48 -> 0.38 | H27: =Допущения!$C$49 -> 0.42 | I27: =Допущения!$C$49 -> 0.42 | J27: =Допущения!$C$49 -> 0.42 | K27: =Допущения!$C$50 -> 0.45 | L27: =Допущения!$C$50 -> 0.45 | M27: =Допущения!$C$50 -> 0.45
A28: Долгосрочное удержание MAU/мес | B28: =Допущения!$C$53 -> 0.9 | C28: =Допущения!$C$53 -> 0.9 | D28: =Допущения!$C$53 -> 0.9 | E28: =Допущения!$C$53 -> 0.9 | F28: =Допущения!$C$53 -> 0.9 | G28: =Допущения!$C$53 -> 0.9 | H28: =Допущения!$C$53 -> 0.9 | I28: =Допущения!$C$53 -> 0.9 | ... M28: =Допущения!$C$53 -> 0.9
A29: MAU (накопленная активная база) | B29: =B23*B27 -> 4735.012 | C29: =B29*C28+C23*C27 -> 9034.341 | D29: =C29*D28+D23*D27 -> 12941.555 | E29: =D29*E28+E23*E27 -> 18995.472 | F29: =E29*F28+F23*F27 -> 24525.713 | G29: =F29*G28+G23*G27 -> 29581.464 | H29: =G29*H28+H23*H27 -> 34247.809 | I29: =H29*I28+I23*I27 -> 38528.513 | J29: =I29*J28+J23*J27 -> 42459.55 | ... M29: =L29*M28+M23*M27 -> 53174.339
A30: DAU (ежедневно активные) | B30: =B29*Допущения!$C$51*Допущения!$C$52 -> 2130.7554 | C30: =C29*Допущения!$C$51*Допущения!$C$52 -> 4065.4534 | D30: =D29*Допущения!$C$51*Допущения!$C$52 -> 5823.6999 | E30: =E29*Допущения!$C$51*Допущения!$C$52 -> 8547.9622 | F30: =F29*Допущения!$C$51*Допущения!$C$52 -> 11036.571 | G30: =G29*Допущения!$C$51*Допущения!$C$52 -> 13311.659 | H30: =H29*Допущения!$C$51*Допущения!$C$52 -> 15411.514 | I30: =I29*Допущения!$C$51*Допущения!$C$52 -> 17337.831 | ... M30: =M29*Допущения!$C$51*Допущения!$C$52 -> 23928.453
A32: C. СРАВНЕНИЕ С КВАРТАЛЬНЫМИ ЦЕЛЯМИ СТРАТЕГИИ
A33: Целевой DAU на конец квартала | B33: — | C33: — | D33: 5000 | E33: — | F33: — | G33: 25000 | H33: — | I33: — | J33: 50000 | K33: — | L33: — | M33: 80000
A34: Факт DAU на конец квартала (модель) | D34: =D30 -> 5823.6999 | G34: =G30 -> 13311.659 | J34: =J30 -> 19106.798 | M34: =M30 -> 23928.453
A35: Отклонение от цели | D35: =(D34-D33)/D33 -> 0.16473997 | G35: =(G34-G33)/G33 -> -0.46753366 | J35: =(J34-J33)/J33 -> -0.61786405 | M35: =(M34-M33)/M33 -> -0.70089434
A37: Накопленные установки на конец квартала | D37: =D24 -> 44745.283 | G37: =G24 -> 103393.13 | J37: =J24 -> 158426.14 | M37: =M24 -> 213053.8

Sheet Доходы
A2: ДОХОДЫ — Premium-подписки, события, итого
B4: Q1 | C4: Q1 | D4: Q1 | E4: Q2 | F4: Q2 | G4: Q2 | H4: Q3 | I4: Q3 | J4: Q3 | K4: Q4 | L4: Q4 | M4: Q4
B5: М1 июн '26 | C5: М2 июл '26 | D5: М3 авг '26 | E5: М4 сен '26 | F5: М5 окт '26 | G5: М6 ноя '26 | H5: М7 дек '26 | I5: М8 янв '27 | J5: М9 фев '27 | K5: М10 мар '27 | L5: М11 апр '27 | M5: М12 май '27 | N5: ИТОГО год
A6: A. PREMIUM — подписчики и MRR
A7: DAU (из листа Воронка) | B7: =Воронка!B30 -> 2130.7554 | C7: =Воронка!C30 -> 4065.4534 | D7: =Воронка!D30 -> 5823.6999 | E7: =Воронка!E30 -> 8547.9622 | F7: =Воронка!F30 -> 11036.571 | G7: =Воронка!G30 -> 13311.659 | H7: =Воронка!H30 -> 15411.514 | I7: =Воронка!I30 -> 17337.831 | ... M7: =Воронка!M30 -> 23928.453
A8: Конверсия DAU → Paid (для квартала) | B8: =Допущения!$C$59 -> 0.001 | C8: =Допущения!$C$59 -> 0.001 | D8: =Допущения!$C$59 -> 0.001 | E8: =Допущения!$C$60 -> 0.002 | F8: =Допущения!$C$60 -> 0.002 | G8: =Допущения!$C$60 -> 0.002 | H8: =Допущения!$C$61 -> 0.003 | I8: =Допущения!$C$61 -> 0.003 | J8: =Допущения!$C$61 -> 0.003 | K8: =Допущения!$C$62 -> 0.004 | L8: =Допущения!$C$62 -> 0.004 | M8: =Допущения!$C$62 -> 0.004
A9: Новые Premium-подписчики / мес | B9: =B7*B8 -> 2.1307554 | C9: =C7*C8 -> 4.0654534 | D9: =D7*D8 -> 5.8236999 | E9: =E7*E8 -> 17.095924 | F9: =F7*F8 -> 22.073142 | G9: =G7*G8 -> 26.623317 | H9: =H7*H8 -> 46.234542 | I9: =I7*I8 -> 52.013493 | ... M9: =M7*M8 -> 95.71381 | N9: =SUM(B9:M9) -> 502.28519
A10: Месячный отток (для квартала) | B10: =Допущения!$C$63 -> 0.08 | C10: =Допущения!$C$63 -> 0.08 | D10: =Допущения!$C$63 -> 0.08 | E10: =Допущения!$C$63 -> 0.08 | F10: =Допущения!$C$63 -> 0.08 | G10: =Допущения!$C$63 -> 0.08 | H10: =Допущения!$C$64 -> 0.06 | I10: =Допущения!$C$64 -> 0.06 | J10: =Допущения!$C$64 -> 0.06 | K10: =Допущения!$C$64 -> 0.06 | L10: =Допущения!$C$64 -> 0.06 | M10: =Допущения!$C$64 -> 0.06
A11: Отток подписчиков / мес | B11: =0 -> 0 | C11: =-B12*C10 -> -0.17046043 | D11: =-C12*D10 -> -0.48205987 | E11: =-D12*E10 -> -0.90939107 | F11: =-E12*F10 -> -2.2043137 | G11: =-F12*G10 -> -3.79382 | H11: =-G12*H10 -> -4.2151348 | I11: =-H12*I10 -> -6.7362992 | J11: =-I12*J10 -> -9.4529309 | ... M11: =-L12*M10 -> -20.981589 | N11: =SUM(B11:M11) -> -77.859822
A12: Cumulative Premium-подписчики (на конец мес) | B12: =B9 -> 2.1307554 | C12: =B12+C9+C11 -> 6.0257484 | D12: =C12+D9+D11 -> 11.367388 | E12: =D12+E9+E11 -> 27.553922 | F12: =E12+F9+F11 -> 47.42275 | G12: =F12+G9+G11 -> 70.252247 | H12: =G12+H9+H11 -> 112.27165 | I12: =H12+I9+I11 -> 157.54885 | J12: =I12+J9+J11 -> 205.41631 | ... M12: =L12+M9+M11 -> 424.42537
A13: ARPU blended (с учётом годовой скидки) | B13: =Допущения!$C$56*(1-Допущения!$C$58*Допущения!$C$57) -> 1365 | C13: =Допущения!$C$56*(1-Допущения!$C$58*Допущения!$C$57) -> 1365 | D13: =Допущения!$C$56*(1-Допущения!$C$58*Допущения!$C$57) -> 1365 | E13: =Допущения!$C$56*(1-Допущения!$C$58*Допущения!$C$57) -> 1365 | F13: =Допущения!$C$56*(1-Допущения!$C$58*Допущения!$C$57) -> 1365 | G13: =Допущения!$C$56*(1-Допущения!$C$58*Допущения!$C$57) -> 1365 | H13: =Допущения!$C$56*(1-Допущения!$C$58*Допущения!$C$57) -> 1365 | I13: =Допущения!$C$56*(1-Допущения!$C$58*Допущения!$C$57) -> 1365 | ... M13: =Допущения!$C$56*(1-Допущения!$C$58*Допущения!$C$57) -> 1365
A14: MRR — Monthly Recurring Revenue | B14: =B12*B13 -> 2908.4811 | C14: =C12*C13 -> 8225.1466 | D14: =D12*D13 -> 15516.485 | E14: =E12*E13 -> 37611.103 | F14: =F12*F13 -> 64732.054 | G14: =G12*G13 -> 95894.317 | H14: =H12*H13 -> 153250.81 | I14: =I12*I13 -> 215054.18 | ... M14: =M12*M13 -> 579340.63
A15: ARR — Annual Recurring Revenue | B15: =B14*12 -> 34901.773 | C15: =C14*12 -> 98701.759 | D15: =D14*12 -> 186197.82 | E15: =E14*12 -> 451333.24 | F15: =F14*12 -> 776784.64 | G15: =G14*12 -> 1150731.8 | H15: =H14*12 -> 1839009.7 | I15: =I14*12 -> 2580650.1 | ... M15: =M14*12 -> 6952087.5
A17: B. PREMIUM ВЫРУЧКА — помесячная признаваемая
A18: Premium revenue (признано в месяце) | B18: =B14 -> 2908.4811 | C18: =C14 -> 8225.1466 | D18: =D14 -> 15516.485 | E18: =E14 -> 37611.103 | F18: =F14 -> 64732.054 | G18: =G14 -> 95894.317 | H18: =H14 -> 153250.81 | I18: =I14 -> 215054.18 | ... M18: =M14 -> 579340.63 | N18: =SUM(B18:M18) -> 2307653.8
A19: + аванс по годовым подпискам (для cashflow) | B19: =B9*Допущения!$C$58*(Допущения!$C$56*12*(1-Допущения!$C$57)-B13) -> 7181.7111 | C19: =C9*Допущения!$C$58*(Допущения!$C$56*12*(1-Допущения!$C$57)-C13) -> 13702.611 | D19: =D9*Допущения!$C$58*(Допущения!$C$56*12*(1-Допущения!$C$57)-D13) -> 19628.78 | E19: =E9*Допущения!$C$58*(Допущения!$C$56*12*(1-Допущения!$C$57)-E13) -> 57621.813 | F19: =F9*Допущения!$C$58*(Допущения!$C$56*12*(1-Допущения!$C$57)-F13) -> 74397.525 | G19: =G9*Допущения!$C$58*(Допущения!$C$56*12*(1-Допущения!$C$57)-G13) -> 89733.891 | H19: =H9*Допущения!$C$58*(Допущения!$C$56*12*(1-Допущения!$C$57)-H13) -> 155833.52 | I19: =I9*Допущения!$C$58*(Допущения!$C$56*12*(1-Допущения!$C$57)-I13) -> 175311.48 | ... M19: =M9*Допущения!$C$58*(Допущения!$C$56*12*(1-Допущения!$C$57)-M13) -> 322603.4 | N19: =SUM(B19:M19) -> 1692952.2
A21: C. СОБЫТИЯ — выручка с ивентов
A22: Кол-во ивентов / мес | B22: 0 | C22: 0 | D22: 1 | E22: 1 | F22: 1 | G22: 1 | H22: 1 | I22: 2 | J22: 1 | K22: 1 | L22: 2 | M22: 1 | N22: =SUM(B22:M22) -> 12
A23: Выручка с ивентов (билеты + спонсоры) | B23: =B22*Допущения!$C$88 -> 0 | C23: =C22*Допущения!$C$88 -> 0 | D23: =D22*Допущения!$C$88 -> 180000 | E23: =E22*Допущения!$C$88 -> 180000 | F23: =F22*Допущения!$C$88 -> 180000 | G23: =G22*Допущения!$C$88 -> 180000 | H23: =H22*Допущения!$C$88 -> 180000 | I23: =I22*Допущения!$C$88 -> 360000 | ... M23: =M22*Допущения!$C$88 -> 180000 | N23: =SUM(B23:M23) -> 2160000
A25: D. ИТОГО ВЫРУЧКА
A26: ВСЕГО признанной выручки / мес | B26: =B18+B23 -> 2908.4811 | C26: =C18+C23 -> 8225.1466 | D26: =D18+D23 -> 195516.49 | E26: =E18+E23 -> 217611.1 | F26: =F18+F23 -> 244732.05 | G26: =G18+G23 -> 275894.32 | H26: =H18+H23 -> 333250.81 | I26: =I18+I23 -> 575054.18 | ... M26: =M18+M23 -> 759340.63 | N26: =SUM(B26:M26) -> 4467653.8
A27: накопленная выручка | B27: =SUM($B$26:B26) -> 2908.4811 | C27: =SUM($B$26:C26) -> 11133.628 | D27: =SUM($B$26:D26) -> 206650.11 | E27: =SUM($B$26:E26) -> 424261.22 | F27: =SUM($B$26:F26) -> 668993.27 | G27: =SUM($B$26:G26) -> 944887.59 | H27: =SUM($B$26:H26) -> 1278138.4 | I27: =SUM($B$26:I26) -> 1853192.6 | ... M27: =SUM($B$26:M26) -> 4467653.8
A29: E. СРАВНЕНИЕ С ЦЕЛЯМИ СТРАТЕГИИ (paid subs)
A30: Целевые paid subs (стратегия) | B30: — | C30: — | D30: 0 | E30: — | F30: — | G30: 500 | H30: — | I30: — | J30: 1200 | K30: — | L30: — | M30: 2000
A31: Факт paid subs (модель) | D31: =D12 -> 11.367388 | G31: =G12 -> 70.252247 | J31: =J12 -> 205.41631 | M31: =M12 -> 424.42537
A32: Отклонение от цели | G32: =(G31-G30)/G30 -> -0.85949551 | J32: =(J31-J30)/J30 -> -0.82881974 | M32: =(M31-M30)/M30 -> -0.78778732

Sheet Расходы
A2: РАСХОДЫ — операционные затраты, помесячно
B4: Q1 | C4: Q1 | D4: Q1 | E4: Q2 | F4: Q2 | G4: Q2 | H4: Q3 | I4: Q3 | J4: Q3 | K4: Q4 | L4: Q4 | M4: Q4
B5: М1 июн '26 | C5: М2 июл '26 | D5: М3 авг '26 | E5: М4 сен '26 | F5: М5 окт '26 | G5: М6 ноя '26 | H5: М7 дек '26 | I5: М8 янв '27 | J5: М9 фев '27 | K5: М10 мар '27 | L5: М11 апр '27 | M5: М12 май '27 | N5: ИТОГО год
A6: A. ФОТ — фонд оплаты труда (с налогами)
A7: Главный редактор | B7: =Допущения!$C$68*1 -> 350000 | C7: =Допущения!$C$68*1 -> 350000 | D7: =Допущения!$C$68*1 -> 350000 | E7: =Допущения!$C$68*1 -> 350000 | F7: =Допущения!$C$68*1 -> 350000 | G7: =Допущения!$C$68*1 -> 350000 | H7: =Допущения!$C$68*1 -> 350000 | I7: =Допущения!$C$68*1 -> 350000 | ... M7: =Допущения!$C$68*1 -> 350000 | N7: =SUM(B7:M7) -> 4200000
A8: Журналист 1 | B8: =Допущения!$C$69*1 -> 180000 | C8: =Допущения!$C$69*1 -> 180000 | D8: =Допущения!$C$69*1 -> 180000 | E8: =Допущения!$C$69*1 -> 180000 | F8: =Допущения!$C$69*1 -> 180000 | G8: =Допущения!$C$69*1 -> 180000 | H8: =Допущения!$C$69*1 -> 180000 | I8: =Допущения!$C$69*1 -> 180000 | ... M8: =Допущения!$C$69*1 -> 180000 | N8: =SUM(B8:M8) -> 2160000
A9: Журналист 2 | B9: =Допущения!$C$69*1 -> 180000 | C9: =Допущения!$C$69*1 -> 180000 | D9: =Допущения!$C$69*1 -> 180000 | E9: =Допущения!$C$69*1 -> 180000 | F9: =Допущения!$C$69*1 -> 180000 | G9: =Допущения!$C$69*1 -> 180000 | H9: =Допущения!$C$69*1 -> 180000 | I9: =Допущения!$C$69*1 -> 180000 | ... M9: =Допущения!$C$69*1 -> 180000 | N9: =SUM(B9:M9) -> 2160000
A10: Fullstack-инженер | B10: =Допущения!$C$70*1 -> 320000 | C10: =Допущения!$C$70*1 -> 320000 | D10: =Допущения!$C$70*1 -> 320000 | E10: =Допущения!$C$70*1 -> 320000 | F10: =Допущения!$C$70*1 -> 320000 | G10: =Допущения!$C$70*1 -> 320000 | H10: =Допущения!$C$70*1 -> 320000 | I10: =Допущения!$C$70*1 -> 320000 | ... M10: =Допущения!$C$70*1 -> 320000 | N10: =SUM(B10:M10) -> 3840000
A11: Дизайнер (0.5 FTE) | B11: =Допущения!$C$71*1 -> 120000 | C11: =Допущения!$C$71*1 -> 120000 | D11: =Допущения!$C$71*1 -> 120000 | E11: =Допущения!$C$71*1 -> 120000 | F11: =Допущения!$C$71*1 -> 120000 | G11: =Допущения!$C$71*1 -> 120000 | H11: =Допущения!$C$71*1 -> 120000 | I11: =Допущения!$C$71*1 -> 120000 | ... M11: =Допущения!$C$71*1 -> 120000 | N11: =SUM(B11:M11) -> 1440000
A12: AI-инженер (0.5 FTE) | B12: =Допущения!$C$72*1 -> 150000 | C12: =Допущения!$C$72*1 -> 150000 | D12: =Допущения!$C$72*1 -> 150000 | E12: =Допущения!$C$72*1 -> 150000 | F12: =Допущения!$C$72*1 -> 150000 | G12: =Допущения!$C$72*1 -> 150000 | H12: =Допущения!$C$72*1 -> 150000 | I12: =Допущения!$C$72*1 -> 150000 | ... M12: =Допущения!$C$72*1 -> 150000 | N12: =SUM(B12:M12) -> 1800000
A13: SMM/рост (нанимаем M4) | B13: 0 | C13: 0 | D13: 0 | E13: =Допущения!$C$73*1 -> 130000 | F13: =Допущения!$C$73*1 -> 130000 | G13: =Допущения!$C$73*1 -> 130000 | H13: =Допущения!$C$73*1 -> 130000 | I13: =Допущения!$C$73*1 -> 130000 | J13: =Допущения!$C$73*1 -> 130000 | K13: =Допущения!$C$73*1 -> 130000 | L13: =Допущения!$C$73*1 -> 130000 | M13: =Допущения!$C$73*1 -> 130000 | N13: =SUM(B13:M13) -> 1170000
A14: Community-менеджер (M7) | B14: 0 | C14: 0 | D14: 0 | E14: 0 | F14: 0 | G14: 0 | H14: =Допущения!$C$74*1 -> 110000 | I14: =Допущения!$C$74*1 -> 110000 | J14: =Допущения!$C$74*1 -> 110000 | K14: =Допущения!$C$74*1 -> 110000 | L14: =Допущения!$C$74*1 -> 110000 | M14: =Допущения!$C$74*1 -> 110000 | N14: =SUM(B14:M14) -> 660000
A15: Итого окладов (gross, без налогов) | B15: =SUM(B7:B14) -> 1300000 | C15: =SUM(C7:C14) -> 1300000 | D15: =SUM(D7:D14) -> 1300000 | E15: =SUM(E7:E14) -> 1430000 | F15: =SUM(F7:F14) -> 1430000 | G15: =SUM(G7:G14) -> 1430000 | H15: =SUM(H7:H14) -> 1540000 | I15: =SUM(I7:I14) -> 1540000 | ... M15: =SUM(M7:M14) -> 1540000 | N15: =SUM(B15:M15) -> 17430000
A16: Налоги и сборы (страховые + НДФЛ-уплифт) | B16: =B15*Допущения!$C$75 -> 390000 | C16: =C15*Допущения!$C$75 -> 390000 | D16: =D15*Допущения!$C$75 -> 390000 | E16: =E15*Допущения!$C$75 -> 429000 | F16: =F15*Допущения!$C$75 -> 429000 | G16: =G15*Допущения!$C$75 -> 429000 | H16: =H15*Допущения!$C$75 -> 462000 | I16: =I15*Допущения!$C$75 -> 462000 | ... M16: =M15*Допущения!$C$75 -> 462000 | N16: =SUM(B16:M16) -> 5229000
A17: ИТОГО ФОТ (с налогами) | B17: =B15+B16 -> 1690000 | C17: =C15+C16 -> 1690000 | D17: =D15+D16 -> 1690000 | E17: =E15+E16 -> 1859000 | F17: =F15+F16 -> 1859000 | G17: =G15+G16 -> 1859000 | H17: =H15+H16 -> 2002000 | I17: =I15+I16 -> 2002000 | ... M17: =M15+M16 -> 2002000 | N17: =SUM(B17:M17) -> 22659000
A19: B. ИНФРАСТРУКТУРА — хостинг, БД, CDN
A20: Базовая инфра (Cloudflare/Neon/Upstash/Vercel) | B20: =Допущения!$C$78 -> 35000 | C20: =Допущения!$C$78 -> 35000 | D20: =Допущения!$C$78 -> 35000 | E20: =Допущения!$C$78 -> 35000 | F20: =Допущения!$C$78 -> 35000 | G20: =Допущения!$C$78 -> 35000 | H20: =Допущения!$C$78 -> 35000 | I20: =Допущения!$C$78 -> 35000 | ... M20: =Допущения!$C$78 -> 35000 | N20: =SUM(B20:M20) -> 420000
A21: Переменная (per 1K DAU свыше 10K) | B21: =MAX(0,Воронка!B30-10000)/1000*Допущения!$C$79 -> 0 | C21: =MAX(0,Воронка!C30-10000)/1000*Допущения!$C$79 -> 0 | D21: =MAX(0,Воронка!D30-10000)/1000*Допущения!$C$79 -> 0 | E21: =MAX(0,Воронка!E30-10000)/1000*Допущения!$C$79 -> 0 | F21: =MAX(0,Воронка!F30-10000)/1000*Допущения!$C$79 -> 1243.8851 | G21: =MAX(0,Воронка!G30-10000)/1000*Допущения!$C$79 -> 3973.9903 | H21: =MAX(0,Воронка!H30-10000)/1000*Допущения!$C$79 -> 6493.8167 | I21: =MAX(0,Воронка!I30-10000)/1000*Допущения!$C$79 -> 8805.3972 | ... M21: =MAX(0,Воронка!M30-10000)/1000*Допущения!$C$79 -> 16714.143 | N21: =SUM(B21:M21) -> 76116.587
A22: ИТОГО Инфра | B22: =B20+B21 -> 35000 | C22: =C20+C21 -> 35000 | D22: =D20+D21 -> 35000 | E22: =E20+E21 -> 35000 | F22: =F20+F21 -> 36243.885 | G22: =G20+G21 -> 38973.99 | H22: =H20+H21 -> 41493.817 | I22: =I20+I21 -> 43805.397 | ... M22: =M20+M21 -> 51714.143 | N22: =SUM(B22:M22) -> 496116.59
A24: C. AI / LLM — стоимость контент-пайплайна
A25: Материалов / мес (ramp) | B25: =Допущения!$C$82+(Допущения!$C$83-Допущения!$C$82)*(1-1)/11 -> 90 | C25: =Допущения!$C$82+(Допущения!$C$83-Допущения!$C$82)*(2-1)/11 -> 104.54545 | D25: =Допущения!$C$82+(Допущения!$C$83-Допущения!$C$82)*(3-1)/11 -> 119.09091 | E25: =Допущения!$C$82+(Допущения!$C$83-Допущения!$C$82)*(4-1)/11 -> 133.63636 | F25: =Допущения!$C$82+(Допущения!$C$83-Допущения!$C$82)*(5-1)/11 -> 148.18182 | G25: =Допущения!$C$82+(Допущения!$C$83-Допущения!$C$82)*(6-1)/11 -> 162.72727 | H25: =Допущения!$C$82+(Допущения!$C$83-Допущения!$C$82)*(7-1)/11 -> 177.27273 | I25: =Допущения!$C$82+(Допущения!$C$83-Допущения!$C$82)*(8-1)/11 -> 191.81818 | J25: =Допущения!$C$82+(Допущения!$C$83-Допущения!$C$82)*(9-1)/11 -> 206.36364 | K25: =Допущения!$C$82+(Допущения!$C$83-Допущения!$C$82)*(10-1)/11 -> 220.90909 | L25: =Допущения!$C$82+(Допущения!$C$83-Допущения!$C$82)*(11-1)/11 -> 235.45455 | M25: =Допущения!$C$82+(Допущения!$C$83-Допущения!$C$82)*(12-1)/11 -> 250
A26: LLM-стоимость контента | B26: =B25*Допущения!$C$80 -> 1080 | C26: =C25*Допущения!$C$80 -> 1254.5455 | D26: =D25*Допущения!$C$80 -> 1429.0909 | E26: =E25*Допущения!$C$80 -> 1603.6364 | F26: =F25*Допущения!$C$80 -> 1778.1818 | G26: =G25*Допущения!$C$80 -> 1952.7273 | H26: =H25*Допущения!$C$80 -> 2127.2727 | I26: =I25*Допущения!$C$80 -> 2301.8182 | ... M26: =M25*Допущения!$C$80 -> 3000 | N26: =SUM(B26:M26) -> 24480
A27: Голосовые саммари (10% статей × 4 мин) | B27: =B25*0.1*4*Допущения!$C$81 -> 288 | C27: =C25*0.1*4*Допущения!$C$81 -> 334.54545 | D27: =D25*0.1*4*Допущения!$C$81 -> 381.09091 | E27: =E25*0.1*4*Допущения!$C$81 -> 427.63636 | F27: =F25*0.1*4*Допущения!$C$81 -> 474.18182 | G27: =G25*0.1*4*Допущения!$C$81 -> 520.72727 | H27: =H25*0.1*4*Допущения!$C$81 -> 567.27273 | I27: =I25*0.1*4*Допущения!$C$81 -> 613.81818 | ... M27: =M25*0.1*4*Допущения!$C$81 -> 800 | N27: =SUM(B27:M27) -> 6528
A28: ИТОГО AI / LLM | B28: =B26+B27 -> 1368 | C28: =C26+C27 -> 1589.0909 | D28: =D26+D27 -> 1810.1818 | E28: =E26+E27 -> 2031.2727 | F28: =F26+F27 -> 2252.3636 | G28: =G26+G27 -> 2473.4545 | H28: =H26+H27 -> 2694.5455 | I28: =I26+I27 -> 2915.6364 | ... M28: =M26+M27 -> 3800 | N28: =SUM(B28:M28) -> 31008
A30: D. МАРКЕТИНГ — платное привлечение
A31: Платный трафик (бюджет из Воронки) | B31: =Воронка!B14 -> 150000 | C31: =Воронка!C14 -> 150000 | D31: =Воронка!D14 -> 150000 | E31: =Воронка!E14 -> 350000 | F31: =Воронка!F14 -> 350000 | G31: =Воронка!G14 -> 350000 | H31: =Воронка!H14 -> 250000 | I31: =Воронка!I14 -> 250000 | ... M31: =Воронка!M14 -> 200000 | N31: =SUM(B31:M31) -> 2850000
A32: Награды реферальной программы (200 ₽ / приглашение) | B32: =Воронка!B21*200 -> 0 | C32: =Воронка!C21*200 -> 0 | D32: =Воронка!D21*200 -> 0 | E32: =Воронка!E21*200 -> 41412.977 | F32: =Воронка!F21*200 -> 60785.509 | G32: =Воронка!G21*200 -> 78482.282 | H32: =Воронка!H21*200 -> 94660.683 | I32: =Воронка!I21*200 -> 109592.99 | ... M32: =Воронка!M21*200 -> 159646.67 | N32: =SUM(B32:M32) -> 951990.75
A33: ИТОГО Маркетинг | B33: =B31+B32 -> 150000 | C33: =C31+C32 -> 150000 | D33: =D31+D32 -> 150000 | E33: =E31+E32 -> 391412.98 | F33: =F31+F32 -> 410785.51 | G33: =G31+G32 -> 428482.28 | H33: =H31+H32 -> 344660.68 | I33: =I31+I32 -> 359592.99 | ... M33: =M31+M32 -> 359646.67 | N33: =SUM(B33:M33) -> 3801990.7
A35: E. СОБЫТИЯ И ПЕЧАТЬ
A36: Стоимость организации ивентов (помесячно) | B36: =Доходы!B22*Допущения!$C$87 -> 0 | C36: =Доходы!C22*Допущения!$C$87 -> 0 | D36: =Доходы!D22*Допущения!$C$87 -> 125000 | E36: =Доходы!E22*Допущения!$C$87 -> 125000 | F36: =Доходы!F22*Допущения!$C$87 -> 125000 | G36: =Доходы!G22*Допущения!$C$87 -> 125000 | H36: =Доходы!H22*Допущения!$C$87 -> 125000 | I36: =Доходы!I22*Допущения!$C$87 -> 250000 | ... M36: =Доходы!M22*Допущения!$C$87 -> 125000 | N36: =SUM(B36:M36) -> 1500000
A37: Печать газеты-сувенира (1 раз в квартал) | B37: 0 | C37: 0 | D37: =Допущения!$C$89 -> 200000 | E37: 0 | F37: 0 | G37: =Допущения!$C$89 -> 200000 | H37: 0 | I37: 0 | J37: =Допущения!$C$89 -> 200000 | K37: 0 | L37: 0 | M37: =Допущения!$C$89 -> 200000 | N37: =SUM(B37:M37) -> 800000
A38: ИТОГО События + Печать | B38: =B36+B37 -> 0 | C38: =C36+C37 -> 0 | D38: =D36+D37 -> 325000 | E38: =E36+E37 -> 125000 | F38: =F36+F37 -> 125000 | G38: =G36+G37 -> 325000 | H38: =H36+H37 -> 125000 | I38: =I36+I37 -> 250000 | ... M38: =M36+M37 -> 325000 | N38: =SUM(B38:M38) -> 2300000
A40: F. G&A — юр / бух / прочие операционные
A41: Юр. сопровождение + бухгалтерия | B41: =Допущения!$C$93 -> 55000 | C41: =Допущения!$C$93 -> 55000 | D41: =Допущения!$C$93 -> 55000 | E41: =Допущения!$C$93 -> 55000 | F41: =Допущения!$C$93 -> 55000 | G41: =Допущения!$C$93 -> 55000 | H41: =Допущения!$C$93 -> 55000 | I41: =Допущения!$C$93 -> 55000 | ... M41: =Допущения!$C$93 -> 55000 | N41: =SUM(B41:M41) -> 660000
A42: Прочие (офис, ПО, командировки) | B42: =Допущения!$C$94 -> 40000 | C42: =Допущения!$C$94 -> 40000 | D42: =Допущения!$C$94 -> 40000 | E42: =Допущения!$C$94 -> 40000 | F42: =Допущения!$C$94 -> 40000 | G42: =Допущения!$C$94 -> 40000 | H42: =Допущения!$C$94 -> 40000 | I42: =Допущения!$C$94 -> 40000 | ... M42: =Допущения!$C$94 -> 40000 | N42: =SUM(B42:M42) -> 480000
A43: Комиссия эквайринга на Premium | B43: =Доходы!B18*Допущения!$C$96 -> 84.345953 | C43: =Доходы!C18*Допущения!$C$96 -> 238.52925 | D43: =Доходы!D18*Допущения!$C$96 -> 449.97807 | E43: =Доходы!E18*Допущения!$C$96 -> 1090.722 | F43: =Доходы!F18*Допущения!$C$96 -> 1877.2296 | G43: =Доходы!G18*Допущения!$C$96 -> 2780.9352 | H43: =Доходы!H18*Допущения!$C$96 -> 4444.2734 | I43: =Доходы!I18*Допущения!$C$96 -> 6236.5711 | ... M43: =Доходы!M18*Допущения!$C$96 -> 16800.878 | N43: =SUM(B43:M43) -> 66921.961
A44: ИТОГО G&A | B44: =B41+B42+B43 -> 95084.346 | C44: =C41+C42+C43 -> 95238.529 | D44: =D41+D42+D43 -> 95449.978 | E44: =E41+E42+E43 -> 96090.722 | F44: =F41+F42+F43 -> 96877.23 | G44: =G41+G42+G43 -> 97780.935 | H44: =H41+H42+H43 -> 99444.273 | I44: =I41+I42+I43 -> 101236.57 | ... M44: =M41+M42+M43 -> 111800.88 | N44: =SUM(B44:M44) -> 1206922
A46: G. ИТОГО OPEX
A47: ВСЕГО OpEx / мес | B47: =B17+B22+B28+B33+B38+B44 -> 1971452.3 | C47: =C17+C22+C28+C33+C38+C44 -> 1971827.6 | D47: =D17+D22+D28+D33+D38+D44 -> 2297260.2 | E47: =E17+E22+E28+E33+E38+E44 -> 2508535 | F47: =F17+F22+F28+F33+F38+F44 -> 2530159 | G47: =G17+G22+G28+G33+G38+G44 -> 2751710.7 | H47: =H17+H22+H28+H33+H38+H44 -> 2615293.3 | I47: =I17+I22+I28+I33+I38+I44 -> 2759550.6 | ... M47: =M17+M22+M28+M33+M38+M44 -> 2853961.7 | N47: =SUM(B47:M47) -> 30495037
A48: накопленные расходы | B48: =SUM($B$47:B47) -> 1971452.3 | C48: =SUM($B$47:C47) -> 3943280 | D48: =SUM($B$47:D47) -> 6240540.1 | E48: =SUM($B$47:E47) -> 8749075.1 | F48: =SUM($B$47:F47) -> 11279234 | G48: =SUM($B$47:G47) -> 14030945 | H48: =SUM($B$47:H47) -> 16646238 | I48: =SUM($B$47:I47) -> 19405789 | ... M48: =SUM($B$47:M47) -> 30495037
...

Sheet P&L
A2: P&L · ОПиУ — отчёт о прибылях и убытках
B4: Q1 | C4: Q1 | D4: Q1 | E4: Q2 | F4: Q2 | G4: Q2 | H4: Q3 | I4: Q3 | J4: Q3 | K4: Q4 | L4: Q4 | M4: Q4
B5: М1 июн '26 | C5: М2 июл '26 | D5: М3 авг '26 | E5: М4 сен '26 | F5: М5 окт '26 | G5: М6 ноя '26 | H5: М7 дек '26 | I5: М8 янв '27 | J5: М9 фев '27 | K5: М10 мар '27 | L5: М11 апр '27 | M5: М12 май '27 | N5: ИТОГО год
A6: ВЫРУЧКА
A7: Premium-подписки (recognized) | B7: =Доходы!B18 -> 2908.4811 | C7: =Доходы!C18 -> 8225.1466 | D7: =Доходы!D18 -> 15516.485 | E7: =Доходы!E18 -> 37611.103 | F7: =Доходы!F18 -> 64732.054 | G7: =Доходы!G18 -> 95894.317 | H7: =Доходы!H18 -> 153250.81 | I7: =Доходы!I18 -> 215054.18 | ... M7: =Доходы!M18 -> 579340.63 | N7: =SUM(B7:M7) -> 2307653.8
A8: Выручка с ивентов | B8: =Доходы!B23 -> 0 | C8: =Доходы!C23 -> 0 | D8: =Доходы!D23 -> 180000 | E8: =Доходы!E23 -> 180000 | F8: =Доходы!F23 -> 180000 | G8: =Доходы!G23 -> 180000 | H8: =Доходы!H23 -> 180000 | I8: =Доходы!I23 -> 360000 | ... M8: =Доходы!M23 -> 180000 | N8: =SUM(B8:M8) -> 2160000
A9: ИТОГО ВЫРУЧКА | B9: =SUM(B7:B8) -> 2908.4811 | C9: =SUM(C7:C8) -> 8225.1466 | D9: =SUM(D7:D8) -> 195516.49 | E9: =SUM(E7:E8) -> 217611.1 | F9: =SUM(F7:F8) -> 244732.05 | G9: =SUM(G7:G8) -> 275894.32 | H9: =SUM(H7:H8) -> 333250.81 | I9: =SUM(I7:I8) -> 575054.18 | ... M9: =SUM(M7:M8) -> 759340.63 | N9: =SUM(B9:M9) -> 4467653.8
A11: COGS — прямые затраты
A12: Инфраструктура | B12: =Расходы!B22 -> 35000 | C12: =Расходы!C22 -> 35000 | D12: =Расходы!D22 -> 35000 | E12: =Расходы!E22 -> 35000 | F12: =Расходы!F22 -> 36243.885 | G12: =Расходы!G22 -> 38973.99 | H12: =Расходы!H22 -> 41493.817 | I12: =Расходы!I22 -> 43805.397 | ... M12: =Расходы!M22 -> 51714.143 | N12: =SUM(B12:M12) -> 496116.59
A13: AI / LLM | B13: =Расходы!B28 -> 1368 | C13: =Расходы!C28 -> 1589.0909 | D13: =Расходы!D28 -> 1810.1818 | E13: =Расходы!E28 -> 2031.2727 | F13: =Расходы!F28 -> 2252.3636 | G13: =Расходы!G28 -> 2473.4545 | H13: =Расходы!H28 -> 2694.5455 | I13: =Расходы!I28 -> 2915.6364 | ... M13: =Расходы!M28 -> 3800 | N13: =SUM(B13:M13) -> 31008
A14: Эквайринг | B14: =Расходы!B43 -> 84.345953 | C14: =Расходы!C43 -> 238.52925 | D14: =Расходы!D43 -> 449.97807 | E14: =Расходы!E43 -> 1090.722 | F14: =Расходы!F43 -> 1877.2296 | G14: =Расходы!G43 -> 2780.9352 | H14: =Расходы!H43 -> 4444.2734 | I14: =Расходы!I43 -> 6236.5711 | ... M14: =Расходы!M43 -> 16800.878 | N14: =SUM(B14:M14) -> 66921.961
A15: ИТОГО COGS | B15: =SUM(B12:B14) -> 36452.346 | C15: =SUM(C12:C14) -> 36827.62 | D15: =SUM(D12:D14) -> 37260.16 | E15: =SUM(E12:E14) -> 38121.995 | F15: =SUM(F12:F14) -> 40373.478 | G15: =SUM(G12:G14) -> 44228.38 | H15: =SUM(H12:H14) -> 48632.636 | I15: =SUM(I12:I14) -> 52957.605 | ... M15: =SUM(M12:M14) -> 72315.021 | N15: =SUM(B15:M15) -> 594046.55
A17: GROSS PROFIT (валовая прибыль) | B17: =B9-B15 -> -33543.865 | C17: =C9-C15 -> -28602.474 | D17: =D9-D15 -> 158256.33 | E17: =E9-E15 -> 179489.11 | F17: =F9-F15 -> 204358.58 | G17: =G9-G15 -> 231665.94 | H17: =H9-H15 -> 284618.17 | I17: =I9-I15 -> 522096.57 | ... M17: =M9-M15 -> 687025.61 | N17: =SUM(B17:M17) -> 3873607.3
A18: Gross Margin % | B18: =IFERROR(B17/B9,"н/п") -> -11.533121 | C18: =IFERROR(C17/C9,"н/п") -> -3.4774424 | D18: =IFERROR(D17/D9,"н/п") -> 0.80942702 | E18: =IFERROR(E17/E9,"н/п") -> 0.82481595 | F18: =IFERROR(F17/F9,"н/п") -> 0.83502987 | G18: =IFERROR(G17/G9,"н/п") -> 0.83969086 | H18: =IFERROR(H17/H9,"н/п") -> 0.85406596 | I18: =IFERROR(I17/I9,"н/п") -> 0.90790849 | ... N18: =IFERROR(N17/N9,"н/п") -> 0.86703389
A20: OPEX (косвенные затраты)
A21: ФОТ (с налогами) | B21: =Расходы!B17 -> 1690000 | C21: =Расходы!C17 -> 1690000 | D21: =Расходы!D17 -> 1690000 | E21: =Расходы!E17 -> 1859000 | F21: =Расходы!F17 -> 1859000 | G21: =Расходы!G17 -> 1859000 | H21: =Расходы!H17 -> 2002000 | I21: =Расходы!I17 -> 2002000 | ... M21: =Расходы!M17 -> 2002000 | N21: =SUM(B21:M21) -> 22659000
A22: Маркетинг | B22: =Расходы!B33 -> 150000 | C22: =Расходы!C33 -> 150000 | D22: =Расходы!D33 -> 150000 | E22: =Расходы!E33 -> 391412.98 | F22: =Расходы!F33 -> 410785.51 | G22: =Расходы!G33 -> 428482.28 | H22: =Расходы!H33 -> 344660.68 | I22: =Расходы!I33 -> 359592.99 | ... M22: =Расходы!M33 -> 359646.67 | N22: =SUM(B22:M22) -> 3801990.7
A23: События + Печать | B23: =Расходы!B38 -> 0 | C23: =Расходы!C38 -> 0 | D23: =Расходы!D38 -> 325000 | E23: =Расходы!E38 -> 125000 | F23: =Расходы!F38 -> 125000 | G23: =Расходы!G38 -> 325000 | H23: =Расходы!H38 -> 125000 | I23: =Расходы!I38 -> 250000 | ... M23: =Расходы!M38 -> 325000 | N23: =SUM(B23:M23) -> 2300000
A24: G&A (юр/бух/прочие) | B24: =Расходы!B44-Расходы!B43 -> 95000 | C24: =Расходы!C44-Расходы!C43 -> 95000 | D24: =Расходы!D44-Расходы!D43 -> 95000 | E24: =Расходы!E44-Расходы!E43 -> 95000 | F24: =Расходы!F44-Расходы!F43 -> 95000 | G24: =Расходы!G44-Расходы!G43 -> 95000 | H24: =Расходы!H44-Расходы!H43 -> 95000 | I24: =Расходы!I44-Расходы!I43 -> 95000 | ... M24: =Расходы!M44-Расходы!M43 -> 95000 | N24: =SUM(B24:M24) -> 1140000
A25: ИТОГО OpEx | B25: =SUM(B21:B24) -> 1935000 | C25: =SUM(C21:C24) -> 1935000 | D25: =SUM(D21:D24) -> 2260000 | E25: =SUM(E21:E24) -> 2470413 | F25: =SUM(F21:F24) -> 2489785.5 | G25: =SUM(G21:G24) -> 2707482.3 | H25: =SUM(H21:H24) -> 2566660.7 | I25: =SUM(I21:I24) -> 2706593 | ... M25: =SUM(M21:M24) -> 2781646.7 | N25: =SUM(B25:M25) -> 29900991
A27: EBITDA | B27: =B17-B25 -> -1968543.9 | C27: =C17-C25 -> -1963602.5 | D27: =D17-D25 -> -2101743.7 | E27: =E17-E25 -> -2290923.9 | F27: =F17-F25 -> -2285426.9 | G27: =G17-G25 -> -2475816.3 | H27: =H17-H25 -> -2282042.5 | I27: =I17-I25 -> -2184496.4 | ... M27: =M17-M25 -> -2094621.1 | N27: =SUM(B27:M27) -> -26027383
A28: EBITDA margin % | B28: =IFERROR(B27/B9,"н/п") -> -676.82883 | C28: =IFERROR(C27/C9,"н/п") -> -238.73161 | D28: =IFERROR(D27/D9,"н/п") -> -10.749701 | E28: =IFERROR(E27/E9,"н/п") -> -10.527606 | F28: =IFERROR(F27/F9,"н/п") -> -9.3384863 | G28: =IFERROR(G27/G9,"н/п") -> -8.9737852 | H28: =IFERROR(H27/H9,"н/п") -> -6.8478229 | I28: =IFERROR(I27/I9,"н/п") -> -3.7987663 | ... N28: =IFERROR(N27/N9,"н/п") -> -5.8257387
A29: Накопленная EBITDA (отслеживание break-even) | B29: =SUM($B$27:B27) -> -1968543.9 | C29: =SUM($B$27:C27) -> -3932146.3 | D29: =SUM($B$27:D27) -> -6033890 | E29: =SUM($B$27:E27) -> -8324813.9 | F29: =SUM($B$27:F27) -> -10610241 | G29: =SUM($B$27:G27) -> -13086057 | H29: =SUM($B$27:H27) -> -15368100 | I29: =SUM($B$27:I27) -> -17552596 | ... M29: =SUM($B$27:M27) -> -26027383
A31: Месяц достижения месячной безубыточности (EBITDA ≥ 0) | N31: =IFERROR("M"&MATCH(TRUE(),INDEX(B27:M27>0,0),0),"не достигается") -> не достигается

Sheet Cashflow
A2: CASHFLOW · ДДС — движение денежных средств
B4: Q1 | C4: Q1 | D4: Q1 | E4: Q2 | F4: Q2 | G4: Q2 | H4: Q3 | I4: Q3 | J4: Q3 | K4: Q4 | L4: Q4 | M4: Q4
B5: М1 июн '26 | C5: М2 июл '26 | D5: М3 авг '26 | E5: М4 сен '26 | F5: М5 окт '26 | G5: М6 ноя '26 | H5: М7 дек '26 | I5: М8 янв '27 | J5: М9 фев '27 | K5: М10 мар '27 | L5: М11 апр '27 | M5: М12 май '27 | N5: ИТОГО год
A6: Остаток на начало месяца | B6: =0 -> 0 | C6: =B20 -> 10038638 | D6: =C20 -> 8088738 | E6: =D20 -> 6006623.1 | F6: =E20 -> 3773321 | G6: =F20 -> 1562291.6 | H6: =G20 -> -823790.83 | I6: =H20 -> -2949999.8 | J6: =I20 -> -4959184.8 | ... M6: =L20 -> -10562414
A8: ПОСТУПЛЕНИЯ
A9: Premium-подписки (cash from monthly billing) | B9: =Доходы!B18 -> 2908.4811 | C9: =Доходы!C18 -> 8225.1466 | D9: =Доходы!D18 -> 15516.485 | E9: =Доходы!E18 -> 37611.103 | F9: =Доходы!F18 -> 64732.054 | G9: =Доходы!G18 -> 95894.317 | H9: =Доходы!H18 -> 153250.81 | I9: =Доходы!I18 -> 215054.18 | ... M9: =Доходы!M18 -> 579340.63 | N9: =SUM(B9:M9) -> 2307653.8
A10: Аванс по годовым подпискам (upfront) | B10: =Доходы!B19 -> 7181.7111 | C10: =Доходы!C19 -> 13702.611 | D10: =Доходы!D19 -> 19628.78 | E10: =Доходы!E19 -> 57621.813 | F10: =Доходы!F19 -> 74397.525 | G10: =Доходы!G19 -> 89733.891 | H10: =Доходы!H19 -> 155833.52 | I10: =Доходы!I19 -> 175311.48 | ... M10: =Доходы!M19 -> 322603.4 | N10: =SUM(B10:M10) -> 1692952.2
A11: Выручка с ивентов | B11: =Доходы!B23 -> 0 | C11: =Доходы!C23 -> 0 | D11: =Доходы!D23 -> 180000 | E11: =Доходы!E23 -> 180000 | F11: =Доходы!F23 -> 180000 | G11: =Доходы!G23 -> 180000 | H11: =Доходы!H23 -> 180000 | I11: =Доходы!I23 -> 360000 | ... M11: =Доходы!M23 -> 180000 | N11: =SUM(B11:M11) -> 2160000
A12: Стартовое финансирование Х10 | B12: =Допущения!$C$95 -> 12000000 | C12: 0 | D12: 0 | E12: 0 | F12: 0 | G12: 0 | H12: 0 | I12: 0 | J12: 0 | K12: 0 | L12: 0 | M12: 0 | N12: =SUM(B12:M12) -> 12000000
A13: ИТОГО ПОСТУПЛЕНИЯ | B13: =SUM(B9:B12) -> 12010090 | C13: =SUM(C9:C12) -> 21927.757 | D13: =SUM(D9:D12) -> 215145.27 | E13: =SUM(E9:E12) -> 275232.92 | F13: =SUM(F9:F12) -> 319129.58 | G13: =SUM(G9:G12) -> 365628.21 | H13: =SUM(H9:H12) -> 489084.33 | I13: =SUM(I9:I12) -> 750365.66 | ... M13: =SUM(M9:M12) -> 1081944 | N13: =SUM(B13:M13) -> 18160606
A15: ВЫПЛАТЫ
A16: Полные операционные расходы | B16: =Расходы!B47 -> 1971452.3 | C16: =Расходы!C47 -> 1971827.6 | D16: =Расходы!D47 -> 2297260.2 | E16: =Расходы!E47 -> 2508535 | F16: =Расходы!F47 -> 2530159 | G16: =Расходы!G47 -> 2751710.7 | H16: =Расходы!H47 -> 2615293.3 | I16: =Расходы!I47 -> 2759550.6 | ... M16: =Расходы!M47 -> 2853961.7 | N16: =SUM(B16:M16) -> 30495037
A17: ИТОГО ВЫПЛАТЫ | B17: =B16 -> 1971452.3 | C17: =C16 -> 1971827.6 | D17: =D16 -> 2297260.2 | E17: =E16 -> 2508535 | F17: =F16 -> 2530159 | G17: =G16 -> 2751710.7 | H17: =H16 -> 2615293.3 | I17: =I16 -> 2759550.6 | ... M17: =M16 -> 2853961.7 | N17: =SUM(B17:M17) -> 30495037
A19: Net cashflow за месяц | B19: =B13-B17 -> 10038638 | C19: =C13-C17 -> -1949899.9 | D19: =D13-D17 -> -2082114.9 | E19: =E13-E17 -> -2233302.1 | F19: =F13-F17 -> -2211029.4 | G19: =G13-G17 -> -2386082.5 | H19: =H13-H17 -> -2126209 | I19: =I13-I17 -> -2009184.9 | ... M19: =M13-M17 -> -1772017.7 | N19: =SUM(B19:M19) -> -12334431
A20: Остаток на конец месяца | B20: =B6+B19 -> 10038638 | C20: =C6+C19 -> 8088738 | D20: =D6+D19 -> 6006623.1 | E20: =E6+E19 -> 3773321 | F20: =F6+F19 -> 1562291.6 | G20: =G6+G19 -> -823790.83 | H20: =H6+H19 -> -2949999.8 | I20: =I6+I19 -> -4959184.8 | ... M20: =M6+M19 -> -12334431
A22: Месяц исчерпания средств (если cash < 0) | N22: =IFERROR("M"&MATCH(TRUE(),INDEX(B20:M20<0,0),0),"средств хватает на 12 мес") -> M6
A23: Минимальный остаток за период | N23: =MIN(B20:M20) -> -12334431
A24: Доп. финансирование, требуемое для М12 (если < 0) | N24: =MAX(0,-MIN(B20:M20)) -> 12334431

Sheet Юнит-экономика
A2: ЮНИТ-ЭКОНОМИКА — CAC, LTV, payback, contribution margin
B4: Q1 | C4: Q1 | D4: Q1 | E4: Q2 | F4: Q2 | G4: Q2 | H4: Q3 | I4: Q3 | J4: Q3 | K4: Q4 | L4: Q4 | M4: Q4
B5: М1 июн '26 | C5: М2 июл '26 | D5: М3 авг '26 | E5: М4 сен '26 | F5: М5 окт '26 | G5: М6 ноя '26 | H5: М7 дек '26 | I5: М8 янв '27 | J5: М9 фев '27 | K5: М10 мар '27 | L5: М11 апр '27 | M5: М12 май '27 | N5: ИТОГО год
A6: A. CAC — стоимость привлечения
A7: CAC mini-app (платный канал) | B7: =Допущения!$C$34 -> 150 | C7: =Допущения!$C$34 -> 150 | D7: =Допущения!$C$34 -> 150 | E7: =Допущения!$C$34 -> 150 | F7: =Допущения!$C$34 -> 150 | G7: =Допущения!$C$34 -> 150 | H7: =Допущения!$C$34 -> 150 | I7: =Допущения!$C$34 -> 150 | ... M7: =Допущения!$C$34 -> 150
A8: ориентир стратегии (≤150 ₽) | B8: 150 | C8: 150 | D8: 150 | E8: 150 | F8: 150 | G8: 150 | H8: 150 | I8: 150 | J8: 150 | K8: 150 | L8: 150 | M8: 150
A10: Маркетинговые расходы / мес | B10: =Расходы!B33 -> 150000 | C10: =Расходы!C33 -> 150000 | D10: =Расходы!D33 -> 150000 | E10: =Расходы!E33 -> 391412.98 | F10: =Расходы!F33 -> 410785.51 | G10: =Расходы!G33 -> 428482.28 | H10: =Расходы!H33 -> 344660.68 | I10: =Расходы!I33 -> 359592.99 | ... M10: =Расходы!M33 -> 359646.67
A11: Новые Premium-подписчики / мес | B11: =Доходы!B9 -> 2.1307554 | C11: =Доходы!C9 -> 4.0654534 | D11: =Доходы!D9 -> 5.8236999 | E11: =Доходы!E9 -> 17.095924 | F11: =Доходы!F9 -> 22.073142 | G11: =Доходы!G9 -> 26.623317 | H11: =Доходы!H9 -> 46.234542 | I11: =Доходы!I9 -> 52.013493 | ... M11: =Доходы!M9 -> 95.71381
A12: CAC Premium (blended, all-in) | B12: =IFERROR(B10/B11,0) -> 70397.569 | C12: =IFERROR(C10/C11,0) -> 36896.253 | D12: =IFERROR(D10/D11,0) -> 25756.822 | E12: =IFERROR(E10/E11,0) -> 22895.105 | F12: =IFERROR(F10/F11,0) -> 18610.197 | G12: =IFERROR(G10/G11,0) -> 16094.248 | H12: =IFERROR(H10/H11,0) -> 7454.6145 | I12: =IFERROR(I10/I11,0) -> 6913.4558 | ... M12: =IFERROR(M10/M11,0) -> 3757.5212
A13: ориентир стратегии (≤1 800 ₽) | B13: 1800 | C13: 1800 | D13: 1800 | E13: 1800 | F13: 1800 | G13: 1800 | H13: 1800 | I13: 1800 | J13: 1800 | K13: 1800 | L13: 1800 | M13: 1800
A15: B. LTV — пожизненная ценность
A16: ARPU blended (₽/мес) | B16: =Доходы!B14/IFERROR(Доходы!B12,1) -> 1365 | C16: =Доходы!C14/IFERROR(Доходы!C12,1) -> 1365 | D16: =Доходы!D14/IFERROR(Доходы!D12,1) -> 1365 | E16: =Доходы!E14/IFERROR(Доходы!E12,1) -> 1365 | F16: =Доходы!F14/IFERROR(Доходы!F12,1) -> 1365 | G16: =Доходы!G14/IFERROR(Доходы!G12,1) -> 1365 | H16: =Доходы!H14/IFERROR(Доходы!H12,1) -> 1365 | I16: =Доходы!I14/IFERROR(Доходы!I12,1) -> 1365 | ... M16: =Доходы!M14/IFERROR(Доходы!M12,1) -> 1365
A17: Средний lifetime подписчика (мес) | B17: =1/Допущения!$C$63 -> 12.5 | C17: =1/Допущения!$C$63 -> 12.5 | D17: =1/Допущения!$C$63 -> 12.5 | E17: =1/Допущения!$C$63 -> 12.5 | F17: =1/Допущения!$C$63 -> 12.5 | G17: =1/Допущения!$C$63 -> 12.5 | H17: =1/Допущения!$C$64 -> 16.666667 | I17: =1/Допущения!$C$64 -> 16.666667 | J17: =1/Допущения!$C$64 -> 16.666667 | K17: =1/Допущения!$C$64 -> 16.666667 | L17: =1/Допущения!$C$64 -> 16.666667 | M17: =1/Допущения!$C$64 -> 16.666667
A18: Gross margin на Premium | B18: =0.85 -> 0.85 | C18: =0.85 -> 0.85 | D18: =0.85 -> 0.85 | E18: =0.85 -> 0.85 | F18: =0.85 -> 0.85 | G18: =0.85 -> 0.85 | H18: =0.85 -> 0.85 | I18: =0.85 -> 0.85 | ... M18: =0.85 -> 0.85
A19: LTV (ARPU × lifetime × GM) | B19: =B16*B17*B18 -> 14503.125 | C19: =C16*C17*C18 -> 14503.125 | D19: =D16*D17*D18 -> 14503.125 | E19: =E16*E17*E18 -> 14503.125 | F19: =F16*F17*F18 -> 14503.125 | G19: =G16*G17*G18 -> 14503.125 | H19: =H16*H17*H18 -> 19337.5 | I19: =I16*I17*I18 -> 19337.5 | ... M19: =M16*M17*M18 -> 19337.5
A20: ориентир стратегии (~19 000 ₽) | B20: 19000 | C20: 19000 | D20: 19000 | E20: 19000 | F20: 19000 | G20: 19000 | H20: 19000 | I20: 19000 | J20: 19000 | K20: 19000 | L20: 19000 | M20: 19000
A22: C. LTV / CAC RATIO
A23: LTV / CAC Premium | B23: =IFERROR(B19/B12,0) -> 0.20601741 | C23: =IFERROR(C19/C12,0) -> 0.39307853 | D23: =IFERROR(D19/D12,0) -> 0.56307898 | E23: =IFERROR(E19/E12,0) -> 0.63345965 | F23: =IFERROR(F19/F12,0) -> 0.77931068 | G23: =IFERROR(G19/G12,0) -> 0.90113714 | H23: =IFERROR(H19/H12,0) -> 2.5940309 | I23: =IFERROR(I19/I12,0) -> 2.7970816 | ... M23: =IFERROR(M19/M12,0) -> 5.1463448
A24: ориентир стратегии (≈10x) | B24: 10 | C24: 10 | D24: 10 | E24: 10 | F24: 10 | G24: 10 | H24: 10 | I24: 10 | J24: 10 | K24: 10 | L24: 10 | M24: 10
A26: D. PAYBACK PERIOD — окупаемость CAC
A27: Месячная contribution margin / подписчик | B27: =B16*B18 -> 1160.25 | C27: =C16*C18 -> 1160.25 | D27: =D16*D18 -> 1160.25 | E27: =E16*E18 -> 1160.25 | F27: =F16*F18 -> 1160.25 | G27: =G16*G18 -> 1160.25 | H27: =H16*H18 -> 1160.25 | I27: =I16*I18 -> 1160.25 | ... M27: =M16*M18 -> 1160.25
A28: Payback period (мес) | B28: =IFERROR(B12/B27,0) -> 60.674483 | C28: =IFERROR(C12/C27,0) -> 31.800261 | D28: =IFERROR(D12/D27,0) -> 22.199372 | E28: =IFERROR(E12/E27,0) -> 19.732906 | F28: =IFERROR(F12/F27,0) -> 16.039816 | G28: =IFERROR(G12/G27,0) -> 13.871363 | H28: =IFERROR(H12/H27,0) -> 6.4250071 | I28: =IFERROR(I12/I27,0) -> 5.9585915 | ... M28: =IFERROR(M12/M27,0) -> 3.2385445
A30: E. КЛЮЧЕВЫЕ ЦИФРЫ НА КОНЕЦ ГОДА (M12)
A31: Cumulative installs (12 мес) | N31: =Воронка!N23 -> 213053.8
A32: Cumulative new paid subs | N32: =Доходы!N9 -> 502.28519
A33: Cumulative paid subs (stock M12) | N33: =Доходы!M12 -> 424.42537
A34: MRR M12 (₽/мес) | N34: =Доходы!M14 -> 579340.63
A35: ARR M12 (₽/год) | N35: =Доходы!M15 -> 6952087.5
A36: Маркетинг за год (₽) | N36: =Расходы!N33 -> 3801990.7
A37: CAC Premium год средний (₽) | N37: =IFERROR(Расходы!N33/Доходы!N9,0) -> 7569.3865
A38: LTV / CAC год M12 | N38: =M23 -> 5.1463448
A39: Payback period (мес) | N39: =M28 -> 3.2385445

Sheet Сценарии
A2: СЦЕНАРИИ — Bear / Base / Bull
A3: Три варианта развития событий при разных уровнях ключевых рычагов
B5: BEAR | C5: BASE (модель) | D5: BULL | E5: Комментарий
A6: ОПИСАНИЕ
A7: Что произошло | B7: Рыбаков снизил активность, инфобиз-стигма прилипла, отток выше ожидаемого | C7: Стратегия исполняется как задумано, реалистичные конверсии и retention | D7: Рыбаков давит CTA в каждом ролике, AI-персонализация выстрелила, viral growth
A8: Вероятность | B8: 20% | C8: 55% | D8: 25%
A10: КЛЮЧЕВЫЕ РЫЧАГИ (предпосылки)
A11: Конверсия Рыбаков organic (%/мес) | B11: 0.0025 | C11: 0.005 | D11: 0.012 | E11: Bull: прямой CTA в каждом ролике + посевы
A12: DAU/MAU stickiness | B12: 0.3 | C12: 0.45 | D12: 0.55 | E12: Bull: ежедневный push в 7:00 + AI feed
A13: Конверсия DAU → Paid Q4 (%/мес) | B13: 0.001 | C13: 0.004 | D13: 0.003 | E13: Bull НЕ выше базы — это % steady-state, не темп
A14: W4 retention Q4 | B14: 0.32 | C14: 0.45 | D14: 0.55 | E14: Bull: персонализация работает, daily habit сложен
A15: Месячный отток paid (Q3-Q4) | B15: 0.1 | C15: 0.06 | D15: 0.04 | E15: Bull: годовые подписки, retention loops
A16: ARPU effective (с учётом скидок) | B16: 1300 | C16: 1365 | D16: 1450 | E16: Bull: меньше скидок, выше доля premium tier
A17: Маркетинг за год (М ₽) | B17: 2 | C17: 3.8 | D17: 6 | E17: Bull: масштабирование платных каналов
A19: РАСЧЁТНЫЕ РЕЗУЛЬТАТЫ (приближение, M12)
A20: DAU на M12 (приближение) | B20: =(Допущения!$C$14*B11*12*1.4+50000)*B14*B12*0.7 -> 8318.3923 | C20: =(Допущения!$C$14*C11*12*1.4+50000)*C14*C12*0.7 -> 28005.718 | D20: =(Допущения!$C$14*D11*12*1.4+50000)*D14*D12*0.7 -> 85583.184 | E20: Цель стратегии Q4: 80 000 DAU
A21: Paid subs на M12 (приближение) | B21: =IFERROR(B20*0.65*B13/B15,0) -> 54.06955 | C21: =IFERROR(C20*0.65*C13/C15,0) -> 1213.5811 | D21: =IFERROR(D20*0.65*D13/D15,0) -> 4172.1802 | E21: Цель стратегии Q4: 2 000 paid
A22: ARR на M12 (₽/год) | B22: =B21*B16*12 -> 843484.98 | C22: =C21*C16*12 -> 19878458 | D22: =D21*D16*12 -> 72595936 | E22: Цель стратегии: ~36 М ₽ ARR
A23: LTV / CAC | B23: =IFERROR((B16*0.85/B15)/(B17*1000000/MAX(B21*0.8,1)),0) -> 0.23898741 | C23: =IFERROR((C16*0.85/C15)/(C17*1000000/MAX(C21*0.8,1)),0) -> 4.9405525 | D23: =IFERROR((D16*0.85/D15)/(D17*1000000/MAX(D21*0.8,1)),0) -> 17.140707 | E23: Цель стратегии: ≈10x
A24: Год EBITDA (М ₽, приближение) | B24: =(B21*B16*6+2200000-(B17*1000000+22700000+2300000+1200000+500000+200000))/1000000 -> -26.278258 | C24: =(C21*C16*6+2200000-(C17*1000000+22700000+2300000+1200000+500000+200000))/1000000 -> -18.560771 | D24: =(D21*D16*6+2200000-(D17*1000000+22700000+2300000+1200000+500000+200000))/1000000 -> 5.5979678 | E24: Bear: глубокий минус. Bull: близко к 0.
A25: Доп. капитал требуется (М ₽) | B25: =MAX(0,-(B24+12)) -> 14.278258 | C25: =MAX(0,-(C24+12)) -> 6.5607708 | D25: =MAX(0,-(D24+12)) -> 0 | E25: При стартовом капитале 12 М ₽
A27: СТРАТЕГИЧЕСКИЕ ВЫВОДЫ
A28: Bear | B28: Срочно пересобираем продукт: цена Premium вдвое (690 ₽), audio-first дайджест, агрессивный pivot.
A29: Base | B29: Гэп от целей стратегии: -70% DAU, -80% paid. Нужно: или больше Рыбакова, или 10-15М ₽ доп. финансирования к M5.
A30: Bull | B30: Близко к целям стратегии. Достижимо ТОЛЬКО при максимальном CTA-режиме у Рыбакова + AI-персонализация работает.

Sheet Dashboard
A1: DASHBOARD — ключевые KPI
A2: Базовый сценарий · обновляется при изменении входов в Допущениях
A4: DAU · M12 | B4: PREMIUM PAID · M12 | C4: MRR · M12 | D4: ARR · M12 | E4: EBITDA · ГОД | F4: CASH · M12
A5: =Воронка!M30 -> 23928.453 | B5: =Доходы!M12 -> 424.42537 | C5: =Доходы!M14 -> 579340.63 | D5: =Доходы!M15 -> 6952087.5 | E5: ='P&L'!N27 -> -26027383 | F5: =Cashflow!M20 -> -12334431
A6: цель стратегии: 80 000 | B6: цель стратегии: 2 000 | C6: monthly recurring revenue | D6: цель стратегии: ~36 М ₽ | E6: год нарастающим | F6: остаток на конец периода
A8: ВЫРУЧКА · ГОД | B8: OPEX · ГОД | C8: GROSS MARGIN | D8: LTV / CAC | E8: PAYBACK PERIOD | F8: ДОП. КАПИТАЛ НУЖЕН
A9: ='P&L'!N9 -> 4467653.8 | B9: =Расходы!N47 -> 30495037 | C9: ='P&L'!N17/'P&L'!N9 -> 0.86703389 | D9: ='Юнит-экономика'!M23 -> 5.1463448 | E9: ='Юнит-экономика'!M28 -> 3.2385445 | F9: =MAX(0,-MIN(Cashflow!B20:M20)) -> 12334431
A10: premium + события | B10: vs бюджет 24.2 М ₽ | C10: цель: 80–90% | D10: цель стратегии: ≈10x | E10: цель: ≤ 6 мес | F10: если cash идёт в минус
A11: ГРАФИКИ — траектории по основным метрикам
A49: Источники данных для графиков (служебные ячейки ниже)
A50: Месяц | B50: DAU | C50: Цель DAU | D50: Paid | E50: Цель Paid | F50: MRR | G50: Cash | H50: Накопл. EBITDA
A51: М1 | B51: =Воронка!B30 -> 2130.7554 | C51: 1666 | D51: =Доходы!B12 -> 2.1307554 | E51: 0 | F51: =Доходы!B14 -> 2908.4811 | G51: =Cashflow!B20 -> 10038638 | H51: ='P&L'!B29 -> -1968543.9
A52: М2 | B52: =Воронка!C30 -> 4065.4534 | C52: 3333 | D52: =Доходы!C12 -> 6.0257484 | E52: 0 | F52: =Доходы!C14 -> 8225.1466 | G52: =Cashflow!C20 -> 8088738 | H52: ='P&L'!C29 -> -3932146.3
A53: М3 | B53: =Воронка!D30 -> 5823.6999 | C53: 5000 | D53: =Доходы!D12 -> 11.367388 | E53: 0 | F53: =Доходы!D14 -> 15516.485 | G53: =Cashflow!D20 -> 6006623.1 | H53: ='P&L'!D29 -> -6033890
A54: М4 | B54: =Воронка!E30 -> 8547.9622 | C54: 11666 | D54: =Доходы!E12 -> 27.553922 | E54: 167 | F54: =Доходы!E14 -> 37611.103 | G54: =Cashflow!E20 -> 3773321 | H54: ='P&L'!E29 -> -8324813.9
A55: М5 | B55: =Воронка!F30 -> 11036.571 | C55: 18333 | D55: =Доходы!F12 -> 47.42275 | E55: 333 | F55: =Доходы!F14 -> 64732.054 | G55: =Cashflow!F20 -> 1562291.6 | H55: ='P&L'!F29 -> -10610241
A56: М6 | B56: =Воронка!G30 -> 13311.659 | C56: 25000 | D56: =Доходы!G12 -> 70.252247 | E56: 500 | F56: =Доходы!G14 -> 95894.317 | G56: =Cashflow!G20 -> -823790.83 | H56: ='P&L'!G29 -> -13086057
A57: М7 | B57: =Воронка!H30 -> 15411.514 | C57: 33333 | D57: =Доходы!H12 -> 112.27165 | E57: 733 | F57: =Доходы!H14 -> 153250.81 | G57: =Cashflow!H20 -> -2949999.8 | H57: ='P&L'!H29 -> -15368100
A58: М8 | B58: =Воронка!I30 -> 17337.831 | C58: 41666 | D58: =Доходы!I12 -> 157.54885 | E58: 967 | F58: =Доходы!I14 -> 215054.18 | G58: =Cashflow!I20 -> -4959184.8 | H58: ='P&L'!I29 -> -17552596
A59: М9 | B59: =Воронка!J30 -> 19106.798 | C59: 50000 | D59: =Доходы!J12 -> 205.41631 | E59: 1200 | F59: =Доходы!J14 -> 280393.26 | G59: =Cashflow!J20 -> -7158080.6 | H59: ='P&L'!J29 -> -19944690
A60: М10 | B60: =Воронка!K30 -> 20847.351 | C60: 60000 | D60: =Доходы!K12 -> 276.48074 | E60: 1467 | F60: =Доходы!K14 -> 377396.21 | G60: =Cashflow!K20 -> -8939810.1 | H60: ='P&L'!K29 -> -22007484
A61: М11 | B61: =Воронка!L30 -> 22450.313 | C61: 70000 | D61: =Доходы!L12 -> 349.69315 | E61: 1733 | F61: =Доходы!L14 -> 477331.14 | G61: =Cashflow!L20 -> -10562414 | H61: ='P&L'!L29 -> -23932762
A62: М12 | B62: =Воронка!M30 -> 23928.453 | C62: 80000 | D62: =Доходы!M12 -> 424.42537 | E62: 2000 | F62: =Доходы!M14 -> 579340.63 | G62: =Cashflow!M20 -> -12334431 | H62: ='P&L'!M29 -> -26027383
